async function run() {
  console.log('Hello, world!')
}
run().catch((e) => {
  console.error(e)
  process.exit(1)
})
process.on('uncaughtException', function (err) {
  console.error('Uncaught exception', err)
  process.exit(1)
})
process.on('unhandledRejection', (reason, p) => {
  console.error('Unhandled Rejection at: Promise', p, 'reason:', reason)
  process.exit(1)
})
